[
    {
        "author_association": "MEMBER",
        "body": "run `python -m ipykernel` to get kernel tracebacks, this may help to find out why. ",
        "created_at": "2020-07-10T15:32:13Z",
        "html_url": "https://github.com/ipython/ipython/issues/12430#issuecomment-656737387",
        "id": 656737387,
        "issue_url": "https://api.github.com/repos/ipython/ipython/issues/12430",
        "node_id": "MDEyOklzc3VlQ29tbWVudDY1NjczNzM4Nw==",
        "performed_via_github_app": null,
        "reactions": {
            "+1": 0,
            "-1": 0,
            "confused": 0,
            "eyes": 0,
            "heart": 0,
            "hooray": 0,
            "laugh": 0,
            "rocket": 0,
            "total_count": 0,
            "url": "https://api.github.com/repos/ipython/ipython/issues/comments/656737387/reactions"
        },
        "updated_at": "2020-07-10T15:32:13Z",
        "url": "https://api.github.com/repos/ipython/ipython/issues/comments/656737387",
        "user": {
            "avatar_url": "https://avatars.githubusercontent.com/u/335567?v=4",
            "events_url": "https://api.github.com/users/Carreau/events{/privacy}",
            "followers_url": "https://api.github.com/users/Carreau/followers",
            "following_url": "https://api.github.com/users/Carreau/following{/other_user}",
            "gists_url": "https://api.github.com/users/Carreau/gists{/gist_id}",
            "gravatar_id": "",
            "html_url": "https://github.com/Carreau",
            "id": 335567,
            "login": "Carreau",
            "node_id": "MDQ6VXNlcjMzNTU2Nw==",
            "organizations_url": "https://api.github.com/users/Carreau/orgs",
            "received_events_url": "https://api.github.com/users/Carreau/received_events",
            "repos_url": "https://api.github.com/users/Carreau/repos",
            "site_admin": false,
            "starred_url": "https://api.github.com/users/Carreau/starred{/owner}{/repo}",
            "subscriptions_url": "https://api.github.com/users/Carreau/subscriptions",
            "type": "User",
            "url": "https://api.github.com/users/Carreau"
        }
    },
    {
        "author_association": "NONE",
        "body": "Thanks for the suggestion, could you let me know if there is something else I need to do to enable tracebacks?\r\nI ran python -m ipykernel --debug and in another console I started qtconsole to connect to this. I still get the crash every 3 seconds, but there is no tracebacks in my debug session, I just get lots of the message below, once per crash. However, if I connect using \r\n\r\n`python console --existing` I get no crash, and ipython works normally\r\n\r\nso it's something related to the qtconsole?\r\n\r\n ```\r\n--->\r\n\r\n[IPKernelApp] execute_request: {'header': {'msg_id': '2216a519-98d0929519812563610ed31d', 'msg_type': 'execute_request',\r\n 'username': 'username', 'session': '8d4c8617-37040df81dc3775994e8766b', 'date': datetime.datetime(2020, 7, 10, 16, 23,\r\n37, 638744, tzinfo=tzutc()), 'version': '5.3'}, 'msg_id': '2216a519-98d0929519812563610ed31d', 'msg_type': 'execute_requ\r\nest', 'parent_header': {}, 'metadata': {}, 'content': {'code': '', 'silent': True, 'store_history': True, 'user_expressi\r\nons': {}, 'allow_stdin': True, 'stop_on_error': True}, 'buffers': []}\r\n[IPKernelApp] {'header': {'msg_id': '467fed1c-24858a1b0bbaccbb9b0b96e5_20', 'msg_type': 'execute_reply', 'username': 'us\r\nername', 'session': '467fed1c-24858a1b0bbaccbb9b0b96e5', 'date': datetime.datetime(2020, 7, 10, 16, 23, 37, 664746, tzin\r\nfo=datetime.timezone.utc), 'version': '5.3'}, 'msg_id': '467fed1c-24858a1b0bbaccbb9b0b96e5_20', 'msg_type': 'execute_rep\r\nly', 'parent_header': {'msg_id': '2216a519-98d0929519812563610ed31d', 'msg_type': 'execute_request', 'username': 'userna\r\nme', 'session': '8d4c8617-37040df81dc3775994e8766b', 'date': datetime.datetime(2020, 7, 10, 16, 23, 37, 638744, tzinfo=t\r\nzutc()), 'version': '5.3'}, 'content': {'status': 'ok', 'execution_count': 0, 'user_expressions': {}, 'payload': []}, 'm\r\netadata': {'started': datetime.datetime(2020, 7, 10, 16, 23, 37, 661746, tzinfo=datetime.timezone.utc), 'dependencies_me\r\nt': True, 'engine': '61684da6-9642-461a-89b7-ce72dd9bdf3f', 'status': 'ok'}, 'tracker': <zmq.sugar.tracker.MessageTracke\r\nr object at 0x00000000050A3310>}\r\n[IPKernelApp]\r\n*** MESSAGE TYPE:execute_request***\r\n[IPKernelApp]    Content: {'code': '', 'silent': True, 'store_history': True, 'user_expressions': {}, 'allow_stdin': Tru\r\ne, 'stop_on_error': True}\r\n   --->\r\n```",
        "created_at": "2020-07-10T16:45:15Z",
        "html_url": "https://github.com/ipython/ipython/issues/12430#issuecomment-656773843",
        "id": 656773843,
        "issue_url": "https://api.github.com/repos/ipython/ipython/issues/12430",
        "node_id": "MDEyOklzc3VlQ29tbWVudDY1Njc3Mzg0Mw==",
        "performed_via_github_app": null,
        "reactions": {
            "+1": 0,
            "-1": 0,
            "confused": 0,
            "eyes": 0,
            "heart": 0,
            "hooray": 0,
            "laugh": 0,
            "rocket": 0,
            "total_count": 0,
            "url": "https://api.github.com/repos/ipython/ipython/issues/comments/656773843/reactions"
        },
        "updated_at": "2020-07-11T06:14:33Z",
        "url": "https://api.github.com/repos/ipython/ipython/issues/comments/656773843",
        "user": {
            "avatar_url": "https://avatars.githubusercontent.com/u/10646418?v=4",
            "events_url": "https://api.github.com/users/penilessquant/events{/privacy}",
            "followers_url": "https://api.github.com/users/penilessquant/followers",
            "following_url": "https://api.github.com/users/penilessquant/following{/other_user}",
            "gists_url": "https://api.github.com/users/penilessquant/gists{/gist_id}",
            "gravatar_id": "",
            "html_url": "https://github.com/penilessquant",
            "id": 10646418,
            "login": "penilessquant",
            "node_id": "MDQ6VXNlcjEwNjQ2NDE4",
            "organizations_url": "https://api.github.com/users/penilessquant/orgs",
            "received_events_url": "https://api.github.com/users/penilessquant/received_events",
            "repos_url": "https://api.github.com/users/penilessquant/repos",
            "site_admin": false,
            "starred_url": "https://api.github.com/users/penilessquant/starred{/owner}{/repo}",
            "subscriptions_url": "https://api.github.com/users/penilessquant/subscriptions",
            "type": "User",
            "url": "https://api.github.com/users/penilessquant"
        }
    },
    {
        "author_association": "NONE",
        "body": "I've been trying to debug this, and have been unable to use any config options. I created a `jupyter_qtconsole_config.py` in \r\n`C:\\ProgramData\\Anaconda3\\envs\\fx_env\\etc\\jupyter\\jupyter_qtconsole_config.py` and put the following there:\r\n\r\n```\r\nc.IPKernelApp.verbose_crash = True\r\nc.KernelRestarter.restart_limit = 0\r\nc.KernelRestarter.debug = True\r\nc.KernelManager.autorestart = False\r\n\r\n```\r\nfrom `https://github.com/jupyter/jupyter_client/issues/94`\r\nHowever, there is no crash report, and it tries to restart...\r\ndoes `jupyter qtconsole` use a different config file or settings?\r\n",
        "created_at": "2020-07-13T03:57:32Z",
        "html_url": "https://github.com/ipython/ipython/issues/12430#issuecomment-657345475",
        "id": 657345475,
        "issue_url": "https://api.github.com/repos/ipython/ipython/issues/12430",
        "node_id": "MDEyOklzc3VlQ29tbWVudDY1NzM0NTQ3NQ==",
        "performed_via_github_app": null,
        "reactions": {
            "+1": 0,
            "-1": 0,
            "confused": 0,
            "eyes": 0,
            "heart": 0,
            "hooray": 0,
            "laugh": 0,
            "rocket": 0,
            "total_count": 0,
            "url": "https://api.github.com/repos/ipython/ipython/issues/comments/657345475/reactions"
        },
        "updated_at": "2020-07-13T03:57:32Z",
        "url": "https://api.github.com/repos/ipython/ipython/issues/comments/657345475",
        "user": {
            "avatar_url": "https://avatars.githubusercontent.com/u/10646418?v=4",
            "events_url": "https://api.github.com/users/penilessquant/events{/privacy}",
            "followers_url": "https://api.github.com/users/penilessquant/followers",
            "following_url": "https://api.github.com/users/penilessquant/following{/other_user}",
            "gists_url": "https://api.github.com/users/penilessquant/gists{/gist_id}",
            "gravatar_id": "",
            "html_url": "https://github.com/penilessquant",
            "id": 10646418,
            "login": "penilessquant",
            "node_id": "MDQ6VXNlcjEwNjQ2NDE4",
            "organizations_url": "https://api.github.com/users/penilessquant/orgs",
            "received_events_url": "https://api.github.com/users/penilessquant/received_events",
            "repos_url": "https://api.github.com/users/penilessquant/repos",
            "site_admin": false,
            "starred_url": "https://api.github.com/users/penilessquant/starred{/owner}{/repo}",
            "subscriptions_url": "https://api.github.com/users/penilessquant/subscriptions",
            "type": "User",
            "url": "https://api.github.com/users/penilessquant"
        }
    },
    {
        "author_association": "NONE",
        "body": " have narrowed it down to the exact problem (I think):\r\n`ipython qtconsole --existing` should just use an existing kernel which I started with `ipython kernel` . I can connect to this kernel using `'ipython console --existing'`. qtconsole connects to this kernel fine too, but embedded in the console is the repeating message 'kernel died, restarting', please see the attached image. I can see from the jupyter/runtime directory that the only kernel is the one I started and is working from from the ipython console. I can confirm that this is every 3 seconds, and if I edit [client.py](https://github.com/jupyter/qtconsole/blob/efa3302d970e1a395ac9130f16a6e864bd3e593a/qtconsole/client.py#L26) to change the hardcoded 3 seconds there to 20 seconds, this message repeats every 20 seconds. Somehow, qtconsole thinks the kernel is dead. If I try to use the kernel from the ipython console, it is very slow to respond, and I get frequent \r\n`  warn('The kernel did not respond properly to an is_complete_request: %s.' % str(msg))`\r\n\r\nI think this is similar to the issue:\r\nhttps://github.com/jupyter/qtconsole/issues/319\r\n\r\nIs there any way to debug this? It if helps, I am connecting via Citrix into a Windows 2008R2 server that is a multiuser box shared among several people simultaneously.\r\n\r\n```\r\nclass QtHBChannel(SuperQObject, HBChannel):\r\n    # A longer timeout than the base class\r\n    time_to_dead = 3.0 #I changed this from 3.0 to 20.0 and I can see the message is once every 20 seconds\r\n\r\n```\r\n![qtconsole](https://user-images.githubusercontent.com/10646418/87380033-3021ba00-c5c4-11ea-8b0f-04c9d98bf25b.png)\r\n",
        "created_at": "2020-07-14T03:24:23Z",
        "html_url": "https://github.com/ipython/ipython/issues/12430#issuecomment-657944192",
        "id": 657944192,
        "issue_url": "https://api.github.com/repos/ipython/ipython/issues/12430",
        "node_id": "MDEyOklzc3VlQ29tbWVudDY1Nzk0NDE5Mg==",
        "performed_via_github_app": null,
        "reactions": {
            "+1": 0,
            "-1": 0,
            "confused": 0,
            "eyes": 0,
            "heart": 0,
            "hooray": 0,
            "laugh": 0,
            "rocket": 0,
            "total_count": 0,
            "url": "https://api.github.com/repos/ipython/ipython/issues/comments/657944192/reactions"
        },
        "updated_at": "2020-07-14T06:14:16Z",
        "url": "https://api.github.com/repos/ipython/ipython/issues/comments/657944192",
        "user": {
            "avatar_url": "https://avatars.githubusercontent.com/u/10646418?v=4",
            "events_url": "https://api.github.com/users/penilessquant/events{/privacy}",
            "followers_url": "https://api.github.com/users/penilessquant/followers",
            "following_url": "https://api.github.com/users/penilessquant/following{/other_user}",
            "gists_url": "https://api.github.com/users/penilessquant/gists{/gist_id}",
            "gravatar_id": "",
            "html_url": "https://github.com/penilessquant",
            "id": 10646418,
            "login": "penilessquant",
            "node_id": "MDQ6VXNlcjEwNjQ2NDE4",
            "organizations_url": "https://api.github.com/users/penilessquant/orgs",
            "received_events_url": "https://api.github.com/users/penilessquant/received_events",
            "repos_url": "https://api.github.com/users/penilessquant/repos",
            "site_admin": false,
            "starred_url": "https://api.github.com/users/penilessquant/starred{/owner}{/repo}",
            "subscriptions_url": "https://api.github.com/users/penilessquant/subscriptions",
            "type": "User",
            "url": "https://api.github.com/users/penilessquant"
        }
    },
    {
        "author_association": "MEMBER",
        "body": "Try to trash all your jupyter kernel specs. (see `jupyter kernelspec list`), the likely reason is you start a kernel from a different environment (?) That crashes.",
        "created_at": "2020-07-14T15:48:46Z",
        "html_url": "https://github.com/ipython/ipython/issues/12430#issuecomment-658257873",
        "id": 658257873,
        "issue_url": "https://api.github.com/repos/ipython/ipython/issues/12430",
        "node_id": "MDEyOklzc3VlQ29tbWVudDY1ODI1Nzg3Mw==",
        "performed_via_github_app": null,
        "reactions": {
            "+1": 0,
            "-1": 0,
            "confused": 0,
            "eyes": 0,
            "heart": 0,
            "hooray": 0,
            "laugh": 0,
            "rocket": 0,
            "total_count": 0,
            "url": "https://api.github.com/repos/ipython/ipython/issues/comments/658257873/reactions"
        },
        "updated_at": "2020-07-14T15:48:46Z",
        "url": "https://api.github.com/repos/ipython/ipython/issues/comments/658257873",
        "user": {
            "avatar_url": "https://avatars.githubusercontent.com/u/335567?v=4",
            "events_url": "https://api.github.com/users/Carreau/events{/privacy}",
            "followers_url": "https://api.github.com/users/Carreau/followers",
            "following_url": "https://api.github.com/users/Carreau/following{/other_user}",
            "gists_url": "https://api.github.com/users/Carreau/gists{/gist_id}",
            "gravatar_id": "",
            "html_url": "https://github.com/Carreau",
            "id": 335567,
            "login": "Carreau",
            "node_id": "MDQ6VXNlcjMzNTU2Nw==",
            "organizations_url": "https://api.github.com/users/Carreau/orgs",
            "received_events_url": "https://api.github.com/users/Carreau/received_events",
            "repos_url": "https://api.github.com/users/Carreau/repos",
            "site_admin": false,
            "starred_url": "https://api.github.com/users/Carreau/starred{/owner}{/repo}",
            "subscriptions_url": "https://api.github.com/users/Carreau/subscriptions",
            "type": "User",
            "url": "https://api.github.com/users/Carreau"
        }
    },
    {
        "author_association": "NONE",
        "body": "I checked and the only kernel spec is in the conda env I created:\r\n\r\n```\r\n(fx_env) C:\\ProgramData\\Anaconda3\\envs>jupyter kernelspec list\r\nAvailable kernels:\r\n  python3    C:\\ProgramData\\Anaconda3\\envs\\fx_env\\share\\jupyter\\kernels\\python3\r\n```\r\n\r\nI deleted that folder, and then just to be safe I ran `jupyter kernelspec list` again, but now it is showing:\r\n\r\n```\r\n(fx_env) C:\\ProgramData\\Anaconda3\\envs>jupyter kernelspec list\r\nAvailable kernels:\r\n  python3    C:\\ProgramData\\Anaconda3\\envs\\fx_env\\lib\\site-packages\\ipykernel\\resources\r\n```\r\n\r\nEven if I delete this folder, this kernel does not go away. I have checked everywhere on this box, there is no other installation of python or anaconda, and this conda env is the only env that I created. The strange error is still there. i.e if I start a kernel, and connect to it using `ipython console --existing` and I do something like this, the print statement does nothing, If I press enter again, or run some otherline, the display shows, but with this error. Starting a qtconsole has the error as above.\r\n\r\n```\r\nMicrosoft Windows [Version 6.1.7601]\r\nCopyright (c) 2009 Microsoft Corporation.  All rights reserved.\r\n\r\nC:\\ProgramData\\Anaconda3\\envs>conda activate fx_env\r\n\r\n(fx_env) C:\\ProgramData\\Anaconda3\\envs> ipython console --existing\r\n[TerminalIPythonApp] WARNING | Subcommand `ipython console` is deprecated and will be removed in future versions.\r\n[TerminalIPythonApp] WARNING | You likely want to use `jupyter console` in the future\r\nJupyter console 6.1.0\r\n\r\nPython 3.8.3 | packaged by conda-forge | (default, Jun  1 2020, 16:59:10) [MSC v.1916 64 bit (AMD64)]\r\nType 'copyright', 'credits' or 'license' for more information\r\nIPython 7.16.1 -- An enhanced Interactive Python. Type '?' for help.\r\n\r\nIn [1]: print('hello')\r\n\r\nIn [2]: print('hello')\r\nhello\r\nC:\\ProgramData\\Anaconda3\\envs\\fx_env\\lib\\site-packages\\jupyter_console\\ptshell.py:662: UserWarning: The kernel did not r\r\nespond properly to an is_complete_request: {'header': {'msg_id': '9bc71aa3-f6732b9b09a9820ddfaec2f4_16', 'msg_type': 'ex\r\necute_reply', 'username': 'username', 'session': '9bc71aa3-f6732b9b09a9820ddfaec2f4', 'date': datetime.datetime(2020, 7,\r\n 16, 10, 56, 11, 693164, tzinfo=tzutc()), 'version': '5.3'}, 'msg_id': '9bc71aa3-f6732b9b09a9820ddfaec2f4_16', 'msg_type\r\n': 'execute_reply', 'parent_header': {'msg_id': 'bc6dcb4b-68f5bbf0eb6d17151c4bfbd4_4', 'msg_type': 'execute_request', 'u\r\nsername': 'username', 'session': 'bc6dcb4b-68f5bbf0eb6d17151c4bfbd4', 'date': datetime.datetime(2020, 7, 16, 10, 56, 11,\r\n 661963, tzinfo=tzutc()), 'version': '5.3'}, 'metadata': {'started': '2020-07-16T10:56:11.661963Z', 'dependencies_met':\r\nTrue, 'engine': 'c55bb21f-7f81-41b8-96c8-2fecfbdd1e13', 'status': 'ok'}, 'content': {'status': 'ok', 'execution_count':\r\n1, 'user_expressions': {}, 'payload': []}, 'buffers': []}.\r\n  warn('The kernel did not respond properly to an is_complete_request: %s.' % str(msg))\r\n\r\nIn [2]:\r\n\r\n\r\n```\r\n\r\n\r\n",
        "created_at": "2020-07-16T11:00:00Z",
        "html_url": "https://github.com/ipython/ipython/issues/12430#issuecomment-659337482",
        "id": 659337482,
        "issue_url": "https://api.github.com/repos/ipython/ipython/issues/12430",
        "node_id": "MDEyOklzc3VlQ29tbWVudDY1OTMzNzQ4Mg==",
        "performed_via_github_app": null,
        "reactions": {
            "+1": 0,
            "-1": 0,
            "confused": 0,
            "eyes": 0,
            "heart": 0,
            "hooray": 0,
            "laugh": 0,
            "rocket": 0,
            "total_count": 0,
            "url": "https://api.github.com/repos/ipython/ipython/issues/comments/659337482/reactions"
        },
        "updated_at": "2020-07-16T11:00:00Z",
        "url": "https://api.github.com/repos/ipython/ipython/issues/comments/659337482",
        "user": {
            "avatar_url": "https://avatars.githubusercontent.com/u/10646418?v=4",
            "events_url": "https://api.github.com/users/penilessquant/events{/privacy}",
            "followers_url": "https://api.github.com/users/penilessquant/followers",
            "following_url": "https://api.github.com/users/penilessquant/following{/other_user}",
            "gists_url": "https://api.github.com/users/penilessquant/gists{/gist_id}",
            "gravatar_id": "",
            "html_url": "https://github.com/penilessquant",
            "id": 10646418,
            "login": "penilessquant",
            "node_id": "MDQ6VXNlcjEwNjQ2NDE4",
            "organizations_url": "https://api.github.com/users/penilessquant/orgs",
            "received_events_url": "https://api.github.com/users/penilessquant/received_events",
            "repos_url": "https://api.github.com/users/penilessquant/repos",
            "site_admin": false,
            "starred_url": "https://api.github.com/users/penilessquant/starred{/owner}{/repo}",
            "subscriptions_url": "https://api.github.com/users/penilessquant/subscriptions",
            "type": "User",
            "url": "https://api.github.com/users/penilessquant"
        }
    },
    {
        "author_association": "MEMBER",
        "body": "At that point I do not know. Maybe it's some antivirus or firewall doing stuff. \r\n\r\nBut honestly at that point that's where I would go modify the code and write\r\n```\r\nwith open('~/log.log', 'a') as f:\r\n    f.writeline(...)\r\n```\r\n\r\nEverywhere to figure out where things fail exactly, but I really don't see what could be happening.",
        "created_at": "2020-07-16T18:55:17Z",
        "html_url": "https://github.com/ipython/ipython/issues/12430#issuecomment-659605008",
        "id": 659605008,
        "issue_url": "https://api.github.com/repos/ipython/ipython/issues/12430",
        "node_id": "MDEyOklzc3VlQ29tbWVudDY1OTYwNTAwOA==",
        "performed_via_github_app": null,
        "reactions": {
            "+1": 0,
            "-1": 0,
            "confused": 0,
            "eyes": 0,
            "heart": 0,
            "hooray": 0,
            "laugh": 0,
            "rocket": 0,
            "total_count": 0,
            "url": "https://api.github.com/repos/ipython/ipython/issues/comments/659605008/reactions"
        },
        "updated_at": "2020-07-16T18:55:17Z",
        "url": "https://api.github.com/repos/ipython/ipython/issues/comments/659605008",
        "user": {
            "avatar_url": "https://avatars.githubusercontent.com/u/335567?v=4",
            "events_url": "https://api.github.com/users/Carreau/events{/privacy}",
            "followers_url": "https://api.github.com/users/Carreau/followers",
            "following_url": "https://api.github.com/users/Carreau/following{/other_user}",
            "gists_url": "https://api.github.com/users/Carreau/gists{/gist_id}",
            "gravatar_id": "",
            "html_url": "https://github.com/Carreau",
            "id": 335567,
            "login": "Carreau",
            "node_id": "MDQ6VXNlcjMzNTU2Nw==",
            "organizations_url": "https://api.github.com/users/Carreau/orgs",
            "received_events_url": "https://api.github.com/users/Carreau/received_events",
            "repos_url": "https://api.github.com/users/Carreau/repos",
            "site_admin": false,
            "starred_url": "https://api.github.com/users/Carreau/starred{/owner}{/repo}",
            "subscriptions_url": "https://api.github.com/users/Carreau/subscriptions",
            "type": "User",
            "url": "https://api.github.com/users/Carreau"
        }
    },
    {
        "author_association": "NONE",
        "body": "I also get this same bug, except that it only happens during the kernel initialization time (when it is loading its startup code). I have only seen it in `qtconsole`, not other Jupyter frontends, such as the kernel gateway server.\r\n\r\n```zsh\r\njupyter qtconsole --style solarized-light '--editor=/Users/evar/scripts//zshlang/wrappers//emacs_nowait.dash {filename}' '--stylesheet=' '--kernel=julia-1.6' '--gui-completion=ncurses' --debug\r\n```\r\n\r\n```\r\n[JupyterQtConsoleApp] Searching ['/Users/evar/Base/_Code/uni/stochastic', '/Users/evar/.jupyter', '/Users/evar/anaconda/etc/jupyter', '/usr/local/etc/jupyter', '/etc/jupyter'] for config files\r\n[JupyterQtConsoleApp] Looking for jupyter_config in /etc/jupyter\r\n[JupyterQtConsoleApp] Looking for jupyter_config in /usr/local/etc/jupyter\r\n[JupyterQtConsoleApp] Looking for jupyter_config in /Users/evar/anaconda/etc/jupyter\r\n[JupyterQtConsoleApp] Looking for jupyter_config in /Users/evar/.jupyter\r\n[JupyterQtConsoleApp] Looking for jupyter_config in /Users/evar/Base/_Code/uni/stochastic\r\n[JupyterQtConsoleApp] Looking for jupyter_qtconsole_config in /etc/jupyter\r\n[JupyterQtConsoleApp] Looking for jupyter_qtconsole_config in /usr/local/etc/jupyter\r\n[JupyterQtConsoleApp] Looking for jupyter_qtconsole_config in /Users/evar/anaconda/etc/jupyter\r\n[JupyterQtConsoleApp] Looking for jupyter_qtconsole_config in /Users/evar/.jupyter\r\n[JupyterQtConsoleApp] Looking for jupyter_qtconsole_config in /Users/evar/Base/_Code/uni/stochastic\r\n[JupyterQtConsoleApp] Connection File not found: /Users/evar/Library/Jupyter/runtime/kernel-30064.json\r\n[JupyterQtConsoleApp] Starting kernel: ['/Applications/Julia-1.6.app/Contents/Resources/julia/bin/julia', '-i', '--color=yes', '--project=@.', '/Users/evar/.julia/packages/IJulia/e8kqU/src/kernel.jl', '/Users/evar/Library/Jupyter/runtime/kernel-30064.json']\r\n[JupyterQtConsoleApp] Connecting to: tcp://127.0.0.1:51235\r\n[JupyterQtConsoleApp] connecting shell channel to tcp://127.0.0.1:51232\r\n[JupyterQtConsoleApp] Connecting to: tcp://127.0.0.1:51232\r\n[JupyterQtConsoleApp] connecting iopub channel to tcp://127.0.0.1:51233\r\n[JupyterQtConsoleApp] Connecting to: tcp://127.0.0.1:51233\r\n[JupyterQtConsoleApp] connecting stdin channel to tcp://127.0.0.1:51234\r\n[JupyterQtConsoleApp] Connecting to: tcp://127.0.0.1:51234\r\n[JupyterQtConsoleApp] connecting heartbeat channel to tcp://127.0.0.1:51236\r\n[JupyterQtConsoleApp] connecting control channel to tcp://127.0.0.1:51235\r\n[JupyterQtConsoleApp] Connecting to: tcp://127.0.0.1:51235\r\n[JupyterQtConsoleApp] WARNING | kernel died: 2.999451160430908\r\n[ Info: Precompiling NightCommon [ceefa148-4121-41f4-a746-dd9e3430b7c6]\r\n\u250c Warning: Package NightCommon does not have Colors in its dependencies:\r\n\u2502 - If you have NightCommon checked out for development and have\r\n\u2502   added Colors as a dependency but haven't updated your primary\r\n\u2502   environment's manifest file, try `Pkg.resolve()`.\r\n\u2502 - Otherwise you may need to report an issue with NightCommon\r\n\u2514 Loading Colors into NightCommon from project dependency, future warnings for NightCommon are suppressed.\r\n[JupyterQtConsoleApp] WARNING | kernel died: 3.004281997680664\r\n[JupyterQtConsoleApp] WARNING | kernel died: 3.0012130737304688\r\n[JupyterQtConsoleApp] WARNING | kernel died: 3.0024468898773193\r\n\u250c Warning: Matcher rofi not installed.\r\n\u2502 See https://github.com/DaveDavenport/rofi for how to install rofi.\r\n\u2502\r\n\u2502 For terminal usage, `peco` is recommended.\r\n\u2502 See https://github.com/peco/peco for how to install peco.\r\n\u2502\r\n\u2514 @ InteractiveCodeSearch ~/.julia/packages/InteractiveCodeSearch/irjIV/src/InteractiveCodeSearch.jl:514\r\n[JupyterQtConsoleApp] WARNING | kernel died: 2.999613046646118\r\n[JupyterQtConsoleApp] WARNING | kernel died: 3.0018229484558105\r\n[JupyterQtConsoleApp] WARNING | kernel died: 2.9993908405303955\r\nStarting kernel event loops.\r\n[JupyterQtConsoleApp] Received history reply with 0 entries\r\n\r\n[JupyterQtConsoleApp] execute_input: {'code': '8*9', 'execution_count': 1}\r\n[JupyterQtConsoleApp] execute_result: {'data': {'text/plain': '72'}, 'metadata': {}, 'execution_count': 1}\r\n[JupyterQtConsoleApp] execute_result: {'data': {'text/plain': '72'}, 'metadata': {}, 'execution_count': 1}\r\n[JupyterQtConsoleApp] execute_reply: {'status': 'ok', 'payload': [], 'user_expressions': {}, 'execution_count': 1}\r\n```\r\n\r\nHere is my `pip freeze`:\r\n\r\n```\r\nappnope @ file:///opt/concourse/worker/volumes/live/6ca6f098-d773-4461-5c91-a24a17435bda/volume/appnope_1606859448531/work\r\nargon2-cffi==21.1.0\r\nastroid==2.5.1\r\nattrs==21.2.0\r\nautopep8==1.5.6\r\nbackcall==0.2.0\r\nbleach==4.1.0\r\ncertifi==2021.5.30\r\ncffi==1.14.6\r\ncharset-normalizer==2.0.6\r\ndecorator==4.4.2\r\ndefusedxml==0.7.1\r\nentrypoints==0.3\r\nidna==3.2\r\nipykernel @ file:///opt/concourse/worker/volumes/live/b72ce213-516a-4998-6411-bacb2eb6d5d1/volume/ipykernel_1607452776186/work/dist/ipykernel-5.3.4-py3-none-any.whl\r\nipython @ file:///opt/concourse/worker/volumes/live/b6fa8b35-b13b-418a-57b4-6cb679de680b/volume/ipython_1614616449865/work\r\nipython-genutils @ file:///tmp/build/80754af9/ipython_genutils_1606773439826/work\r\nipywidgets==7.6.5\r\nisort==5.8.0\r\njedi==0.18.0\r\nJinja2==3.0.1\r\njsonschema==4.0.1\r\njupyter==1.0.0\r\njupyter-client==7.0.5\r\njupyter-console==6.4.0\r\njupyter-core==4.8.1\r\njupyter-kernel-gateway==2.5.1\r\njupyterlab-pygments==0.1.2\r\njupyterlab-widgets==1.0.2\r\nlazy-object-proxy==1.5.2\r\nMarkupSafe==2.0.1\r\nmccabe==0.6.1\r\nmistune==0.8.4\r\nnbclient==0.5.4\r\nnbconvert==6.2.0\r\nnbformat==5.1.3\r\nnest-asyncio==1.5.1\r\nnotebook==6.4.4\r\nnumpy==1.20.1\r\npackaging==21.0\r\npandocfilters==1.5.0\r\nparso==0.8.1\r\npexpect @ file:///tmp/build/80754af9/pexpect_1605563209008/work\r\npickleshare @ file:///tmp/build/80754af9/pickleshare_1606932040724/work\r\nprometheus-client==0.11.0\r\nprompt-toolkit @ file:///tmp/build/80754af9/prompt-toolkit_1602688806899/work\r\nptyprocess @ file:///tmp/build/80754af9/ptyprocess_1609355006118/work/dist/ptyprocess-0.7.0-py2.py3-none-any.whl\r\npycodestyle==2.7.0\r\npycparser==2.20\r\nPygments @ file:///tmp/build/80754af9/pygments_1600458456400/work\r\npylint==2.7.2\r\npyparsing==2.4.7\r\npyrsistent==0.18.0\r\npython-dateutil==2.8.1\r\npyzmq==20.0.0\r\nqtconsole @ file:///tmp/build/80754af9/qtconsole_1632739723211/work\r\nQtPy==1.11.2\r\nrequests==2.26.0\r\nscipy==1.6.1\r\nSend2Trash==1.8.0\r\nsip==4.19.13\r\nsix==1.15.0\r\nterminado==0.12.1\r\ntestpath==0.5.0\r\ntoml==0.10.2\r\ntornado @ file:///opt/concourse/worker/volumes/live/2c1a63a2-006b-48ee-56b9-0cfe8b4927f9/volume/tornado_1606942321278/work\r\ntraitlets @ file:///tmp/build/80754af9/traitlets_1602787416690/work\r\nurllib3==1.26.7\r\nwcwidth @ file:///tmp/build/80754af9/wcwidth_1593447189090/work\r\nwebencodings==0.5.1\r\nwidgetsnbextension==3.5.1\r\nwrapt==1.12.1\r\n```",
        "created_at": "2021-10-02T08:24:13Z",
        "html_url": "https://github.com/ipython/ipython/issues/12430#issuecomment-932710753",
        "id": 932710753,
        "issue_url": "https://api.github.com/repos/ipython/ipython/issues/12430",
        "node_id": "IC_kwDOAAoMVs43mAlh",
        "performed_via_github_app": null,
        "reactions": {
            "+1": 0,
            "-1": 0,
            "confused": 0,
            "eyes": 0,
            "heart": 0,
            "hooray": 0,
            "laugh": 0,
            "rocket": 0,
            "total_count": 0,
            "url": "https://api.github.com/repos/ipython/ipython/issues/comments/932710753/reactions"
        },
        "updated_at": "2021-10-02T09:07:08Z",
        "url": "https://api.github.com/repos/ipython/ipython/issues/comments/932710753",
        "user": {
            "avatar_url": "https://avatars.githubusercontent.com/u/36224762?v=4",
            "events_url": "https://api.github.com/users/NightMachinery/events{/privacy}",
            "followers_url": "https://api.github.com/users/NightMachinery/followers",
            "following_url": "https://api.github.com/users/NightMachinery/following{/other_user}",
            "gists_url": "https://api.github.com/users/NightMachinery/gists{/gist_id}",
            "gravatar_id": "",
            "html_url": "https://github.com/NightMachinery",
            "id": 36224762,
            "login": "NightMachinery",
            "node_id": "MDQ6VXNlcjM2MjI0NzYy",
            "organizations_url": "https://api.github.com/users/NightMachinery/orgs",
            "received_events_url": "https://api.github.com/users/NightMachinery/received_events",
            "repos_url": "https://api.github.com/users/NightMachinery/repos",
            "site_admin": false,
            "starred_url": "https://api.github.com/users/NightMachinery/starred{/owner}{/repo}",
            "subscriptions_url": "https://api.github.com/users/NightMachinery/subscriptions",
            "type": "User",
            "url": "https://api.github.com/users/NightMachinery"
        }
    }
]